<robot name = "Two Link Manipulator">
    <link name = "link1">
        <!-- <inertial>
            <mass value=1.0>
            <origin rpy="0 0 0" xyz=""/>
        </inertial> -->
    </link>

    <link name = "link2">
        <inertial>

        </inertial>
    </link>

    <link name = "link3">
        <inertial>
        </inertial>
    </link>

    <joint name = "joint1" type = "revolute">
        <parent link = "link1"/>
        <child link = "link2"/>
    </joint>

    <joint name = "joint2" type = "revolute">
        <parent link = "link2"/>
        <child link = "link3"/>
    </joint>
</robot>