<?xml version="1.0"?>
<robot xmlns:xacro="http://www.ros.org/wiki/xacro" name="rsd_robot">
<!-- <robot name="rsd_robot"> -->
    <material name="red">
        <color rgba="1.0 0.0 0.0 1.0"/>
    </material>

    <material name="green">
        <color rgba="0.0 1.0 0.0 1.0"/>
    </material>

    <material name="blue">
        <color rgba="0.0 0.0 1.0 1.0"/>
    </material>

    <material name='black'>
        <color rgba='0.0 0.0 0.0 1.0'/>
    </material>

    <material name='white'>
        <color rgba='1.0 1.0 1.0 1.0'/>
    </material>

    <material name='orange'>
        <color rgba='1.0 0.4 0.0 1.0'/>
    </material>

    <material name='yellow'>
        <color rgba='1.0 1.0 0.0 1.0'/>
    </material>

    <material name="LightGrey">
        <color rgba="0.7 0.7 0.7 1.0"/>
    </material>

    <link name="base_link"/>

    <joint name="chassis_joint" type="fixed">
        <parent link="base_link"/>
        <child link="chassis"/>
        <origin xyz="-0.1 0 0"/>
    </joint>

    <link name="chassis">
        <visual>
            <origin xyz="0.15 0 0.075"/>
            <geometry>
                <box size="0.3 0.3 0.15"/>
                <!-- <mesh filename="../meshes/ee.obj" scale="0.001"/> -->
            </geometry>
            <material name="white"/>
        </visual>

        <collision>
            <origin xyz="0.15 0 0.075"/>
            <geometry>
                <box size="0.3 0.3 0.15"/>
                <!-- <mesh filename="../meshes/ee.obj" scale="0.001"/> -->
            </geometry>
        </collision>
    </link>

    <joint name="left_wheel_joint" type="continuous">
        <parent link="base_link"/>
        <child link="left_wheel"/>
        <origin xyz="0.0 0.175 0.0" rpy="-1.5708 0 0"/>
        <axis xyz="0 0 1"/>
    </joint>

    <link name="left_wheel">
        <visual>
            <geometry>
                <cylinder radius="0.05" length="0.04"/>
            </geometry>
            <material name="blue"/>
        </visual>

        <collision>
            <geometry>
                <cylinder radius="0.05" length="0.04"/>
            </geometry>
        </collision>
    </link>

    <joint name="right_wheel_joint" type="continuous">
        <parent link="base_link"/>
        <child link="right_wheel"/>
        <origin xyz="0.0 -0.175 0.0" rpy="1.5708 0 0"/>
        <axis xyz="0 0 1"/>
    </joint>

    <link name="right_wheel">
        <visual>
            <geometry>
                <cylinder radius="0.05" length="0.04"/>
            </geometry>
            <material name="blue"/>
        </visual>    

        <collision>
            <geometry>
                <cylinder radius="0.05" length="0.04"/>
            </geometry>
        </collision>
    </link>

    <joint name="caster_wheel_joint" type="fixed">
        <parent link="chassis"/>
        <child link="caster_wheel"/>
        <origin xyz="0.24 0 0"/>
    </joint>

    <link name="caster_wheel">
        <visual>
            <geometry>
                <sphere radius="0.05"/>
            </geometry>
            <material name="yellow"/>
        </visual>

        <collision>
            <geometry>
                <sphere radius="0.05"/>
            </geometry>
        </collision>
    </link>
</robot>